Workbook
Name Slicer_Region: #N/A
Name Slicer_Country: #N/A
Name Slicer_Channel: #N/A
Name Slicer_Salesperson: #N/A
Name Slicer_ProductCategory: #N/A
Name Slicer_OrderDate: #N/A

Sheet Data
A1: OrderID | B1: OrderDate | C1: RequiredDate | D1: Region | E1: Country | F1: City | G1: CustomerSegment | H1: Channel | I1: Salesperson | J1: ProductCategory | K1: SKU | L1: UnitCost | M1: UnitPrice | N1: DiscountPct | O1: Quantity
A2: ORD-2024-275203 | B2: 45362 | C2: 45388 | D2: Africa | E2: Kenya | F2: Kisumu | G2: Corporate | H2: Retail | I2: C. Otieno | J2: Components | K2: CMP-8270 | L2: 279.24 | M2: 608.9 | N2: 0.112 | O2: 9
A3: ORD-2024-358795 | B3: 45588 | C3: 45587 | D3: Africa | E3: Nigeria | F3: Port Harcourt | G3: Education | H3: Online | I3: J. Njeri | J3: Printers | K3: PRN-9322 | L3: 1084.39 | M3: 759.33 | N3: 0.237 | O3: 31
A4: ORD-2023-373538 | B4: 44985 | C4: 45010 | D4: Africa | E4: Kenya | F4: Nairobi | G4: Corporate | H4: Retail | I4: I. Johnson | J4: Networking | K4: NET-9666 | L4: 1460.76 | M4: -30.66 | N4: 0.131 | O4: 12
A5: ORD-2025-168148 | B5: 45745 | C5: 45749 | D5: Africa | E5: Nigeria | F5: Lagos | G5: Non-Profit | H5: Marketplace | I5: G. Dubois | J5: Phones | K5: PHN-4556 | L5: 259.93 | M5: 255.94 | N5: 0.072 | O5: 22
A6: ORD-2023-824839 | B6: 45266 | C6: 45291 | D6: Asia | E6: Japan | F6: Osaka | G6: Consumer | H6: Retail | I6: L. Okafor | J6: Printers | K6: PRN-8041 | L6: 663.03 | M6: 813.51 | N6: 0.102 | O6: 15
A7: ORD-2023-723587 | B7: 44928 | C7: 44931 | D7: Americas | E7: Canada | F7: Toronto | G7: Corporate | H7: Distributor | I7: B. Chen | J7: Laptops | K7: LAP-8555 | L7: 315.87 | M7: 591.68 | N7: 0 | O7: 7
A8: ORD-2024-336584 | B8: 45653 | C8: 45671 | D8: Asia | E8: India | F8: Bengaluru | G8: Small Business | H8: Marketplace | I8: E. Garcia | J8: Monitors | K8: MON-8629 | L8: 586.07 | M8: 845.97 | N8: 0.147 | O8: 4
A9: ORD-2023-112666 | B9: 44941 | C9: 44939 | D9: Africa | E9: Nigeria | F9: Abuja | G9: Education | H9: Online | I9: O. Wang | J9: Printers | K9: PRN-6276 | L9: 28.38 | M9: 47.22 | N9: 0.194 | O9: 18
A10: ORD-2024-589570 | B10: 45416 | C10: 45441 | D10: Africa | E10: Nigeria | F10: Abuja | G10: Non-Profit | H10: Marketplace | I10: O. Wang | J10: Monitors | K10: MON-6892 | L10: 1295.34 | M10: 2530.81 | N10: 0.031 | O10: 6
A11: ORD-2025-997421 | B11: 45798 | C11: 45817 | D11: Americas | E11: Brazil | F11: São Paulo | G11: Non-Profit | H11: Online | I11: A. Patel | J11: Components | K11: CMP-3731 | L11: 1331.38 | M11: 2309.56 | N11: 0.149 | O11: 31
A12: ORD-2024-210687 | B12: 45319 | C12: 45331 | D12: Europe | E12: Germany | F12: Berlin | G12: Corporate | H12: Online | I12: G. Dubois | J12: Accessories | K12: ACC-7938 | L12: 644.17 | M12: 700.12 | N12: 0.006 | O12: 23
A13: ORD-2025-515515 | B13: 45660 | C13: 45680 | D13: Asia | E13: Japan | F13: Osaka | G13: Corporate | H13: Distributor | I13: F. Müller | J13: Phones | K13: PHN-7019 | L13: 908.6 | M13: 691.37 | N13: 0.25 | O13: 20
... A34: ORD-2025-474710 | B34: 45862 | C34: 45875 | D34: Africa | E34: South Africa | F34: Johannesburg | G34: Education | H34: Marketplace | I34: D. Smith | J34: Networking | K34: NET-7966 | L34: 1463.9 | M34: 2633.02 | N34: 0.084 | O34: 4
A35: ORD-2024-629525 | B35: 45400 | C35: 45420 | D35: Europe | E35: United Kingdom | F35: London | G35: Non-Profit | I35: D. Smith | J35: Laptops | K35: LAP-9932 | L35: 645.33 | M35: 1321.85 | N35: 0 | O35: 10
A36: ORD-2024-167215 | B36: 45527 | C36: 45525 | D36: Africa | E36: South Africa | F36: Johannesburg | G36: Education | H36: Retail | I36: E. Garcia | J36: Components | K36: CMP-1559 | L36: 1432.52 | M36: 3036.87 | N36: 0 | O36: 9
A37: ORD-2023-864121 | B37: 45012 | C37: 45038 | D37: Asia | E37: India | F37: Delhi | G37: Non-Profit | H37: Marketplace | I37: J. Njeri | J37: Printers | K37: PRN-4506 | L37: 178.53 | M37: 199.37 | N37: 0.101 | O37: 37
A38: ORD-2024-692673 | B38: 45358 | C38: 45376 | D38: Europe | E38: Germany | F38: Munich | G38: Corporate | H38: Online | I38: B. Chen | J38: Components | K38: CMP-7617 | L38: 712.84 | M38: 927.51 | N38: 0.243 | O38: 27
A39: ORD-2025-718992 | B39: 45832 | C39: 45848 | D39: Asia | E39: China | F39: Shanghai | G39: Enterprise | H39: Direct | I39: N. Brown | J39: Components | K39: CMP-8390 | L39: 757.19 | M39: 1735.41 | N39: 0.136 | O39: 8
A40: ORD-2024-599522 | B40: 45401 | C40: 45418 | D40: Africa | E40: Nigeria | F40: Port Harcourt | G40: Non-Profit | H40: Online | I40: A. Patel | J40: Printers | K40: PRN-7303 | L40: 865.33 | M40: 1395.64 | N40: 0.175 | O40: 13
A41: ORD-2023-651638 | B41: 45094 | C41: 45101 | D41: Americas | E41: USA | F41: San Francisco | G41: Corporate | H41: Retail | I41: I. Johnson | J41: Printers | K41: PRN-6536 | L41: 313.99 | M41: 454.42 | N41: 0.129 | O41: 9
A42: ORD-2024-635626 | B42: 45531 | C42: 45554 | D42: Europe | E42: Germany | F42: Berlin | G42: Small Business | H42: Direct | I42: D. Smith | J42: Monitors | K42: MON-9967 | L42: 1024.01 | M42: 1580.97 | N42: 0.037 | O42: 27
A43: ORD-2024-296582 | B43: 45302 | C43: 45324 | D43: Africa | E43: South Africa | F43: Durban | G43: Consumer | H43: Online | I43: K. Singh | J43: Networking | K43: NET-1412 | L43: 1206.2 | M43: 1759.79 | N43: 0 | O43: 6
A44: ORD-2024-998320 | B44: 45590 | C44: 45610 | D44: Africa | E44: Kenya | F44: Mombasa | G44: Corporate | H44: Direct | I44: H. Kim | J44: Printers | K44: PRN-3143 | L44: 1396.48 | M44: 3204.5 | N44: 0.318 | O44: 14
A45: ORD-2025-820255 | B45: 45806 | C45: 45828 | D45: Europe | E45: Germany | F45: Berlin | G45: Corporate | H45: Direct | I45: A. Patel | J45: Printers | K45: PRN-9787 | L45: 483.47 | M45: 1135.43 | N45: 0.146 | O45: 11
A46: ORD-2024-389336 | B46: 45432 | C46: 45445 | D46: Americas | E46: Canada | F46: Vancouver | G46: Enterprise | H46: Marketplace | I46: K. Singh | J46: Components | K46: CMP-5946 | L46: 675.43 | M46: 996.36 | N46: 0.182 | O46: 22
A47: ORD-2023-308124 | B47: 45035 | C47: 45046 | D47: Asia | E47: India | F47: Delhi | G47: Small Business | H47: Retail | I47: A. Patel | J47: Networking | K47: NET-2062 | L47: 826.55 | M47: 1397.05 | N47: 0.169 | O47: 28
... A77: ORD-2023-722117 | B77: 45187 | C77: 45207 | D77: Asia | E77: India | F77: Delhi | G77: Small Business | H77: Direct | I77: B. Chen | J77: Components | K77: CMP-1009 | L77: 825.64 | M77: 1108.43 | N77: 0.114 | O77: 7
A78: ORD-2024-446699 | B78: 45532 | C78: 45560 | D78: Americas | E78: Brazil | F78: Rio de Janeiro | G78: Non-Profit | H78: Online | J78: Accessories | K78: ACC-4490 | L78: 1394.65 | M78: 3144.1 | N78: 0.134 | O78: 13
A79: ORD-2024-451005 | B79: 45473 | C79: 45471 | D79: Americas | E79: Brazil | F79: Rio de Janeiro | G79: Small Business | H79: Direct | I79: L. Okafor | J79: Accessories | K79: ACC-9162 | L79: 1112.98 | M79: 2095.73 | N79: 0.072 | O79: 17
A80: ORD-2023-290279 | B80: 45091 | C80: 45093 | D80: Europe | E80: United Kingdom | F80: Manchester | G80: Non-Profit | H80: Direct | I80: K. Singh | J80: Components | K80: CMP-5820 | L80: 357.36 | M80: 703.62 | N80: 0.257 | O80: 20
A81: ORD-2024-192263 | B81: 45617 | C81: 45647 | D81: Europe | E81: France | F81: Marseille | G81: Small Business | H81: Direct | I81: I. Johnson | J81: Monitors | K81: MON-7943 | L81: 1122.68 | M81: 1997.19 | N81: 0.186 | O81: 3
A82: ORD-2023-159379 | B82: 44965 | C82: 44968 | D82: Africa | E82: South Africa | F82: Cape Town | G82: Corporate | H82: Direct | I82: M. Rossi | J82: Networking | K82: NET-5018 | L82: 1410.05 | M82: 2763.95 | N82: 0.161 | O82: 26
A83: ORD-2023-343322 | B83: 45157 | C83: 45181 | D83: Americas | E83: Canada | F83: Vancouver | G83: Enterprise | H83: Retail | I83: I. Johnson | J83: Printers | K83: PRN-9669 | L83: 1183.95 | M83: 1503.53 | N83: 0.241 | O83: 16
A84: ORD-2025-114382 | B84: 45791 | C84: 45801 | D84: Europe | E84: France | F84: Paris | G84: Small Business | H84: Marketplace | I84: K. Singh | J84: Components | K84: CMP-2865 | L84: 170.39 | M84: 388.04 | N84: 0.084 | O84: 15
A85: ORD-2025-488349 | B85: 45770 | C85: 45769 | D85: Americas | E85: USA | F85: San Francisco | G85: Non-Profit | H85: Distributor | I85: D. Smith | J85: Monitors | K85: MON-3371 | L85: 23.24 | M85: 44.57 | N85: 0.215 | O85: 15
A86: ORD-2025-330203 | B86: 45741 | C86: 45764 | D86: Europe | E86: United Kingdom | F86: London | G86: Consumer | H86: Retail | I86: H. Kim | J86: Networking | K86: NET-7166 | L86: 1421.19 | M86: 1808.26 | N86: 0.104 | O86: 13
A87: ORD-2023-841426 | B87: 45282 | C87: 45283 | D87: Africa | E87: South Africa | F87: Cape Town | G87: Non-Profit | H87: Marketplace | I87: D. Smith | J87: Components | K87: CMP-4531 | L87: 1186.18 | M87: 1285.09 | N87: 0.07 | O87: 11
A88: ORD-2024-594592 | B88: 45388 | C88: 45407 | D88: Asia | E88: China | F88: Shanghai | G88: Corporate | H88: Retail | I88: K. Singh | J88: Components | K88: CMP-8196 | L88: 1366.48 | M88: 1678.14 | N88: 0.154 | O88: 10
A89: ORD-2025-863978 | B89: 45876 | C89: 45888 | D89: Africa | E89: Kenya | F89: Nakuru | G89: Corporate | I89: M. Rossi | J89: Components | K89: CMP-2854 | L89: 601.51 | M89: 679.35 | N89: 0.188 | O89: 3
...

Sheet Brief
A1: Assignment
A2: Excel Mastery Assignment: Sales Operations & Analytics
A4: Overview:
A5: You are an analyst for a multi-regional electronics distributor. The 'Data' sheet contains 632 rows and 15 columns of transactional data with intentional data-quality issues.
A6: Your job is to clean, enrich, analyze, and present insights via a dynamic dashboard.
A8: Part A — Data Cleaning & Preparation:
A9: 1) Create a staging table where you:
A10: • Remove exact duplicate rows (define and document your duplicate criteria).
A11: • Fix data types (dates as Dates, numeric fields as numbers).
A12: • Handle missing values for City, Salesperson, and Channel using reasonable business logic (document your approach).
A13: • Flag and correct suspicious UnitPrice values (e.g., negative prices) and discounts (e.g., > 30%).
A14: • Ensure RequiredDate is not earlier than OrderDate; where it is, impute a corrected RequiredDate (explain your rule).
... A67: 15) Ensure your dashboard responds to slicers without broken references.

Sheet 1. Staging Table
A1: OrderID | B1: OrderDate | C1: Month Of OrderDate | D1: Month | E1: Quarter | F1: RequiredDate | G1: Corrected Required Date | H1: LeadTime Days | I1: On-Time | J1: Region | K1: Country | L1: City | M1: CustomerSegment | N1: Channel | O1: Salesperson | P1: ProductCategory | Q1: SKU | R1: UnitCost | S1: UnitPrice | T1: Corrected Unit price | U1: UnitCost Inflation Factor | V1: Derived Price Band | W1: DiscountPct | X1: DiscountPct> 20% | Y1: Global DiscountCap | Z1: Quantity | AA1: Quantity Uplift | AB1: GrossRevenue | AC1: WhatIfRevenue | AD1: CostOfGoods | AE1: GrossProfit | AF1: WhatIfProfit | AG1: MarginPct
A2: ORD-2024-275203 | B2: 45362 | C2: =MONTH(B2) -> 3 | D2: =B2 -> 45362 | E2: =IF(AND(MONTH(B2)>=1,MONTH(B2)<=3),"Quarter 1",IF(AND(MONTH(B2)>=4,MONTH(B2)<=6),"Quarter 2",IF(AND(MONTH(B2)>=7,MONTH(B2)<=9),"Quarter 3",IF(AND(MONTH(B2)>=10,MONTH(B2)<=12),"Quarter 4")))) -> Quarter 1 | F2: 45388 | G2: =IF(B2>F2,B2+7,F2) -> 45388 | H2: =G2-B2 -> 26 | I2: =IF(H2<=7,"Ontime","Delayed ") -> Delayed | J2: Africa | K2: Kenya | L2: Kisumu | M2: Corporate | N2: Retail | O2: C. Otieno | P2: Components | Q2: CMP-8270 | R2: 279.24 | S2: 608.9 | T2: =IF(S2<=0,R2,S2) -> 608.9 | U2: =(1+'10. Whatif Control pannel'!$B$6)*T2 -> 681.968 | V2: =IF(T2<=_xlfn.PERCENTILE.INC(T2:T633,33%),"Low",IF(T2<=_xlfn.PERCENTILE.INC(T2:T633,67%),"Medium","High")) -> Low | W2: 0.112 | X2: =IF(W2>0.2,"High Discount","Okay") -> Okay | Y2: =IF(W2<=0.25,W2,'10. Whatif Control pannel'!$B$2) -> 0.112 | Z2: 9 | AA2: =(1+'10. Whatif Control pannel'!$B$10)*Z2 -> 10.8 | AB2: =T2*Z2*(1-W2) -> 4866.3288 | AC2: =U2*AA2*(1-Y2) -> 6540.3459 | AD2: =R2*Z2 -> 2513.16 | AE2: =AB2-AD2 -> 2353.1688 | AF2: =AC2-AD2 -> 4027.1859 | AG2: =IF(AB2=0,0,AE2/AB2) -> 0.48356141
A3: ORD-2024-358795 | B3: 45588 | C3: =MONTH(B3) -> 10 | D3: =B3 -> 45588 | E3: =IF(AND(MONTH(B3)>=1,MONTH(B3)<=3),"Quarter 1",IF(AND(MONTH(B3)>=4,MONTH(B3)<=6),"Quarter 2",IF(AND(MONTH(B3)>=7,MONTH(B3)<=9),"Quarter 3",IF(AND(MONTH(B3)>=10,MONTH(B3)<=12),"Quarter 4")))) -> Quarter 4 | F3: 45587 | G3: =IF(B3>F3,B3+7,F3) -> 45595 | H3: =G3-B3 -> 7 | I3: =IF(H3<=7,"Ontime","Delayed ") -> Ontime | J3: Africa | K3: Nigeria | L3: Port Harcourt | M3: Education | N3: Online | O3: J. Njeri | P3: Printers | Q3: PRN-9322 | R3: 1084.39 | S3: 759.33 | T3: =IF(S3<=0,R3,S3) -> 759.33 | U3: =(1+'10. Whatif Control pannel'!$B$6)*T3 -> 850.4496 | V3: =IF(T3<=_xlfn.PERCENTILE.INC(T3:T634,33%),"Low",IF(T3<=_xlfn.PERCENTILE.INC(T3:T634,67%),"Medium","High")) -> Low | W3: 0.237 | X3: =IF(W3>0.2,"High Discount","Okay") -> High Discount | Y3: =IF(W3<=0.25,W3,'10. Whatif Control pannel'!$B$2) -> 0.237 | Z3: 31 | AA3: =(1+'10. Whatif Control pannel'!$B$10)*Z3 -> 37.2 | AB3: =T3*Z3*(1-W3) -> 17960.432 | AC3: =U3*AA3*(1-Y3) -> 24138.821 | AD3: =R3*Z3 -> 33616.09 | AE3: =AB3-AD3 -> -15655.658 | AF3: =AC3-AD3 -> -9477.2687 | AG3: =IF(AB3=0,0,AE3/AB3) -> -0.87167486
A4: ORD-2023-373538 | B4: 44985 | C4: =MONTH(B4) -> 2 | D4: =B4 -> 44985 | E4: =IF(AND(MONTH(B4)>=1,MONTH(B4)<=3),"Quarter 1",IF(AND(MONTH(B4)>=4,MONTH(B4)<=6),"Quarter 2",IF(AND(MONTH(B4)>=7,MONTH(B4)<=9),"Quarter 3",IF(AND(MONTH(B4)>=10,MONTH(B4)<=12),"Quarter 4")))) -> Quarter 1 | F4: 45010 | G4: =IF(B4>F4,B4+7,F4) -> 45010 | H4: =G4-B4 -> 25 | I4: =IF(H4<=7,"Ontime","Delayed ") -> Delayed | J4: Africa | K4: Kenya | L4: Nairobi | M4: Corporate | N4: Retail | O4: I. Johnson | P4: Networking | Q4: NET-9666 | R4: 1460.76 | S4: -30.66 | T4: =IF(S4<=0,R4,S4) -> 1460.76 | U4: =(1+'10. Whatif Control pannel'!$B$6)*T4 -> 1636.0512 | V4: =IF(T4<=_xlfn.PERCENTILE.INC(T4:T635,33%),"Low",IF(T4<=_xlfn.PERCENTILE.INC(T4:T635,67%),"Medium","High")) -> Medium | W4: 0.131 | X4: =IF(W4>0.2,"High Discount","Okay") -> Okay | Y4: =IF(W4<=0.25,W4,'10. Whatif Control pannel'!$B$2) -> 0.131 | Z4: 12 | AA4: =(1+'10. Whatif Control pannel'!$B$10)*Z4 -> 14.4 | AB4: =T4*Z4*(1-W4) -> 15232.805 | AC4: =U4*AA4*(1-Y4) -> 20472.89 | AD4: =R4*Z4 -> 17529.12 | AE4: =AB4-AD4 -> -2296.3147 | AF4: =AC4-AD4 -> 2943.7703 | AG4: =IF(AB4=0,0,AE4/AB4) -> -0.15074799
A5: ORD-2025-168148 | B5: 45745 | C5: =MONTH(B5) -> 3 | D5: =B5 -> 45745 | E5: =IF(AND(MONTH(B5)>=1,MONTH(B5)<=3),"Quarter 1",IF(AND(MONTH(B5)>=4,MONTH(B5)<=6),"Quarter 2",IF(AND(MONTH(B5)>=7,MONTH(B5)<=9),"Quarter 3",IF(AND(MONTH(B5)>=10,MONTH(B5)<=12),"Quarter 4")))) -> Quarter 1 | F5: 45749 | G5: =IF(B5>F5,B5+7,F5) -> 45749 | H5: =G5-B5 -> 4 | I5: =IF(H5<=7,"Ontime","Delayed ") -> Ontime | J5: Africa | K5: Nigeria | L5: Lagos | M5: Non-Profit | N5: Marketplace | O5: G. Dubois | P5: Phones | Q5: PHN-4556 | R5: 259.93 | S5: 255.94 | T5: =IF(S5<=0,R5,S5) -> 255.94 | U5: =(1+'10. Whatif Control pannel'!$B$6)*T5 -> 286.6528 | V5: =IF(T5<=_xlfn.PERCENTILE.INC(T5:T636,33%),"Low",IF(T5<=_xlfn.PERCENTILE.INC(T5:T636,67%),"Medium","High")) -> Low | W5: 0.072 | X5: =IF(W5>0.2,"High Discount","Okay") -> Okay | Y5: =IF(W5<=0.25,W5,'10. Whatif Control pannel'!$B$2) -> 0.072 | Z5: 22 | AA5: =(1+'10. Whatif Control pannel'!$B$10)*Z5 -> 26.4 | AB5: =T5*Z5*(1-W5) -> 5225.271 | AC5: =U5*AA5*(1-Y5) -> 7022.7643 | AD5: =R5*Z5 -> 5718.46 | AE5: =AB5-AD5 -> -493.18896 | AF5: =AC5-AD5 -> 1304.3043 | AG5: =IF(AB5=0,0,AE5/AB5) -> -0.094385335
A6: ORD-2023-824839 | B6: 45266 | C6: =MONTH(B6) -> 12 | D6: =B6 -> 45266 | E6: =IF(AND(MONTH(B6)>=1,MONTH(B6)<=3),"Quarter 1",IF(AND(MONTH(B6)>=4,MONTH(B6)<=6),"Quarter 2",IF(AND(MONTH(B6)>=7,MONTH(B6)<=9),"Quarter 3",IF(AND(MONTH(B6)>=10,MONTH(B6)<=12),"Quarter 4")))) -> Quarter 4 | F6: 45291 | G6: =IF(B6>F6,B6+7,F6) -> 45291 | H6: =G6-B6 -> 25 | I6: =IF(H6<=7,"Ontime","Delayed ") -> Delayed | J6: Asia | K6: Japan | L6: Osaka | M6: Consumer | N6: Retail | O6: L. Okafor | P6: Printers | Q6: PRN-8041 | R6: 663.03 | S6: 813.51 | T6: =IF(S6<=0,R6,S6) -> 813.51 | U6: =(1+'10. Whatif Control pannel'!$B$6)*T6 -> 911.1312 | V6: =IF(T6<=_xlfn.PERCENTILE.INC(T6:T637,33%),"Low",IF(T6<=_xlfn.PERCENTILE.INC(T6:T637,67%),"Medium","High")) -> Low | W6: 0.102 | X6: =IF(W6>0.2,"High Discount","Okay") -> Okay | Y6: =IF(W6<=0.25,W6,'10. Whatif Control pannel'!$B$2) -> 0.102 | Z6: 15 | AA6: =(1+'10. Whatif Control pannel'!$B$10)*Z6 -> 18 | AB6: =T6*Z6*(1-W6) -> 10957.98 | AC6: =U6*AA6*(1-Y6) -> 14727.525 | AD6: =R6*Z6 -> 9945.45 | AE6: =AB6-AD6 -> 1012.5297 | AF6: =AC6-AD6 -> 4782.0747 | AG6: =IF(AB6=0,0,AE6/AB6) -> 0.092401129
A7: ORD-2023-723587 | B7: 44928 | C7: =MONTH(B7) -> 1 | D7: =B7 -> 44928 | E7: =IF(AND(MONTH(B7)>=1,MONTH(B7)<=3),"Quarter 1",IF(AND(MONTH(B7)>=4,MONTH(B7)<=6),"Quarter 2",IF(AND(MONTH(B7)>=7,MONTH(B7)<=9),"Quarter 3",IF(AND(MONTH(B7)>=10,MONTH(B7)<=12),"Quarter 4")))) -> Quarter 1 | F7: 44931 | G7: =IF(B7>F7,B7+7,F7) -> 44931 | H7: =G7-B7 -> 3 | I7: =IF(H7<=7,"Ontime","Delayed ") -> Ontime | J7: Americas | K7: Canada | L7: Toronto | M7: Corporate | N7: Distributor | O7: B. Chen | P7: Laptops | Q7: LAP-8555 | R7: 315.87 | S7: 591.68 | T7: =IF(S7<=0,R7,S7) -> 591.68 | U7: =(1+'10. Whatif Control pannel'!$B$6)*T7 -> 662.6816 | V7: =IF(T7<=_xlfn.PERCENTILE.INC(T7:T638,33%),"Low",IF(T7<=_xlfn.PERCENTILE.INC(T7:T638,67%),"Medium","High")) -> Low | W7: 0 | X7: =IF(W7>0.2,"High Discount","Okay") -> Okay | Y7: =IF(W7<=0.25,W7,'10. Whatif Control pannel'!$B$2) -> 0 | Z7: 7 | AA7: =(1+'10. Whatif Control pannel'!$B$10)*Z7 -> 8.4 | AB7: =T7*Z7*(1-W7) -> 4141.76 | AC7: =U7*AA7*(1-Y7) -> 5566.5254 | AD7: =R7*Z7 -> 2211.09 | AE7: =AB7-AD7 -> 1930.67 | AF7: =AC7-AD7 -> 3355.4354 | AG7: =IF(AB7=0,0,AE7/AB7) -> 0.46614724
A8: ORD-2024-336584 | B8: 45653 | C8: =MONTH(B8) -> 12 | D8: =B8 -> 45653 | E8: =IF(AND(MONTH(B8)>=1,MONTH(B8)<=3),"Quarter 1",IF(AND(MONTH(B8)>=4,MONTH(B8)<=6),"Quarter 2",IF(AND(MONTH(B8)>=7,MONTH(B8)<=9),"Quarter 3",IF(AND(MONTH(B8)>=10,MONTH(B8)<=12),"Quarter 4")))) -> Quarter 4 | F8: 45671 | G8: =IF(B8>F8,B8+7,F8) -> 45671 | H8: =G8-B8 -> 18 | I8: =IF(H8<=7,"Ontime","Delayed ") -> Delayed | J8: Asia | K8: India | L8: Bengaluru | M8: Small Business | N8: Marketplace | O8: E. Garcia | P8: Monitors | Q8: MON-8629 | R8: 586.07 | S8: 845.97 | T8: =IF(S8<=0,R8,S8) -> 845.97 | U8: =(1+'10. Whatif Control pannel'!$B$6)*T8 -> 947.4864 | V8: =IF(T8<=_xlfn.PERCENTILE.INC(T8:T639,33%),"Low",IF(T8<=_xlfn.PERCENTILE.INC(T8:T639,67%),"Medium","High")) -> Medium | W8: 0.147 | X8: =IF(W8>0.2,"High Discount","Okay") -> Okay | Y8: =IF(W8<=0.25,W8,'10. Whatif Control pannel'!$B$2) -> 0.147 | Z8: 4 | AA8: =(1+'10. Whatif Control pannel'!$B$10)*Z8 -> 4.8 | AB8: =T8*Z8*(1-W8) -> 2886.4496 | AC8: =U8*AA8*(1-Y8) -> 3879.3883 | AD8: =R8*Z8 -> 2344.28 | AE8: =AB8-AD8 -> 542.16964 | AF8: =AC8-AD8 -> 1535.1083 | AG8: =IF(AB8=0,0,AE8/AB8) -> 0.1878327
A9: ORD-2023-112666 | B9: 44941 | C9: =MONTH(B9) -> 1 | D9: =B9 -> 44941 | E9: =IF(AND(MONTH(B9)>=1,MONTH(B9)<=3),"Quarter 1",IF(AND(MONTH(B9)>=4,MONTH(B9)<=6),"Quarter 2",IF(AND(MONTH(B9)>=7,MONTH(B9)<=9),"Quarter 3",IF(AND(MONTH(B9)>=10,MONTH(B9)<=12),"Quarter 4")))) -> Quarter 1 | F9: 44939 | G9: =IF(B9>F9,B9+7,F9) -> 44948 | H9: =G9-B9 -> 7 | I9: =IF(H9<=7,"Ontime","Delayed ") -> Ontime | J9: Africa | K9: Nigeria | L9: Abuja | M9: Education | N9: Online | O9: O. Wang | P9: Printers | Q9: PRN-6276 | R9: 28.38 | S9: 47.22 | T9: =IF(S9<=0,R9,S9) -> 47.22 | U9: =(1+'10. Whatif Control pannel'!$B$6)*T9 -> 52.8864 | V9: =IF(T9<=_xlfn.PERCENTILE.INC(T9:T640,33%),"Low",IF(T9<=_xlfn.PERCENTILE.INC(T9:T640,67%),"Medium","High")) -> Low | W9: 0.194 | X9: =IF(W9>0.2,"High Discount","Okay") -> Okay | Y9: =IF(W9<=0.25,W9,'10. Whatif Control pannel'!$B$2) -> 0.194 | Z9: 18 | AA9: =(1+'10. Whatif Control pannel'!$B$10)*Z9 -> 21.6 | AB9: =T9*Z9*(1-W9) -> 685.06776 | AC9: =U9*AA9*(1-Y9) -> 920.73107 | AD9: =R9*Z9 -> 510.84 | AE9: =AB9-AD9 -> 174.22776 | AF9: =AC9-AD9 -> 409.89107 | AG9: =IF(AB9=0,0,AE9/AB9) -> 0.25432194
A10: ORD-2024-589570 | B10: 45416 | C10: =MONTH(B10) -> 5 | D10: =B10 -> 45416 | E10: =IF(AND(MONTH(B10)>=1,MONTH(B10)<=3),"Quarter 1",IF(AND(MONTH(B10)>=4,MONTH(B10)<=6),"Quarter 2",IF(AND(MONTH(B10)>=7,MONTH(B10)<=9),"Quarter 3",IF(AND(MONTH(B10)>=10,MONTH(B10)<=12),"Quarter 4")))) -> Quarter 2 | F10: 45441 | G10: =IF(B10>F10,B10+7,F10) -> 45441 | H10: =G10-B10 -> 25 | I10: =IF(H10<=7,"Ontime","Delayed ") -> Delayed | J10: Africa | K10: Nigeria | L10: Abuja | M10: Non-Profit | N10: Marketplace | O10: O. Wang | P10: Monitors | Q10: MON-6892 | R10: 1295.34 | S10: 2530.81 | T10: =IF(S10<=0,R10,S10) -> 2530.81 | U10: =(1+'10. Whatif Control pannel'!$B$6)*T10 -> 2834.5072 | V10: =IF(T10<=_xlfn.PERCENTILE.INC(T10:T641,33%),"Low",IF(T10<=_xlfn.PERCENTILE.INC(T10:T641,67%),"Medium","High")) -> High | W10: 0.031 | X10: =IF(W10>0.2,"High Discount","Okay") -> Okay | Y10: =IF(W10<=0.25,W10,'10. Whatif Control pannel'!$B$2) -> 0.031 | Z10: 6 | AA10: =(1+'10. Whatif Control pannel'!$B$10)*Z10 -> 7.2 | AB10: =T10*Z10*(1-W10) -> 14714.129 | AC10: =U10*AA10*(1-Y10) -> 19775.79 | AD10: =R10*Z10 -> 7772.04 | AE10: =AB10-AD10 -> 6942.0893 | AF10: =AC10-AD10 -> 12003.75 | AG10: =IF(AB10=0,0,AE10/AB10) -> 0.47179749
A11: ORD-2025-997421 | B11: 45798 | C11: =MONTH(B11) -> 5 | D11: =B11 -> 45798 | E11: =IF(AND(MONTH(B11)>=1,MONTH(B11)<=3),"Quarter 1",IF(AND(MONTH(B11)>=4,MONTH(B11)<=6),"Quarter 2",IF(AND(MONTH(B11)>=7,MONTH(B11)<=9),"Quarter 3",IF(AND(MONTH(B11)>=10,MONTH(B11)<=12),"Quarter 4")))) -> Quarter 2 | F11: 45817 | G11: =IF(B11>F11,B11+7,F11) -> 45817 | H11: =G11-B11 -> 19 | I11: =IF(H11<=7,"Ontime","Delayed ") -> Delayed | J11: Americas | K11: Brazil | L11: São Paulo | M11: Non-Profit | N11: Online | O11: A. Patel | P11: Components | Q11: CMP-3731 | R11: 1331.38 | S11: 2309.56 | T11: =IF(S11<=0,R11,S11) -> 2309.56 | U11: =(1+'10. Whatif Control pannel'!$B$6)*T11 -> 2586.7072 | V11: =IF(T11<=_xlfn.PERCENTILE.INC(T11:T642,33%),"Low",IF(T11<=_xlfn.PERCENTILE.INC(T11:T642,67%),"Medium","High")) -> High | W11: 0.149 | X11: =IF(W11>0.2,"High Discount","Okay") -> Okay | Y11: =IF(W11<=0.25,W11,'10. Whatif Control pannel'!$B$2) -> 0.149 | Z11: 31 | AA11: =(1+'10. Whatif Control pannel'!$B$10)*Z11 -> 37.2 | AB11: =T11*Z11*(1-W11) -> 60928.502 | AC11: =U11*AA11*(1-Y11) -> 81887.907 | AD11: =R11*Z11 -> 41272.78 | AE11: =AB11-AD11 -> 19655.722 | AF11: =AC11-AD11 -> 40615.127 | AG11: =IF(AB11=0,0,AE11/AB11) -> 0.32260308
A12: ORD-2024-210687 | B12: 45319 | C12: =MONTH(B12) -> 1 | D12: =B12 -> 45319 | E12: =IF(AND(MONTH(B12)>=1,MONTH(B12)<=3),"Quarter 1",IF(AND(MONTH(B12)>=4,MONTH(B12)<=6),"Quarter 2",IF(AND(MONTH(B12)>=7,MONTH(B12)<=9),"Quarter 3",IF(AND(MONTH(B12)>=10,MONTH(B12)<=12),"Quarter 4")))) -> Quarter 1 | F12: 45331 | G12: =IF(B12>F12,B12+7,F12) -> 45331 | H12: =G12-B12 -> 12 | I12: =IF(H12<=7,"Ontime","Delayed ") -> Delayed | J12: Europe | K12: Germany | L12: Berlin | M12: Corporate | N12: Online | O12: G. Dubois | P12: Accessories | Q12: ACC-7938 | R12: 644.17 | S12: 700.12 | T12: =IF(S12<=0,R12,S12) -> 700.12 | U12: =(1+'10. Whatif Control pannel'!$B$6)*T12 -> 784.1344 | V12: =IF(T12<=_xlfn.PERCENTILE.INC(T12:T643,33%),"Low",IF(T12<=_xlfn.PERCENTILE.INC(T12:T643,67%),"Medium","High")) -> Low | W12: 0.006 | X12: =IF(W12>0.2,"High Discount","Okay") -> Okay | Y12: =IF(W12<=0.25,W12,'10. Whatif Control pannel'!$B$2) -> 0.006 | Z12: 23 | AA12: =(1+'10. Whatif Control pannel'!$B$10)*Z12 -> 27.6 | AB12: =T12*Z12*(1-W12) -> 16006.143 | AC12: =U12*AA12*(1-Y12) -> 21512.257 | AD12: =R12*Z12 -> 14815.91 | AE12: =AB12-AD12 -> 1190.2334 | AF12: =AC12-AD12 -> 6696.3468 | AG12: =IF(AB12=0,0,AE12/AB12) -> 0.074361038
A13: ORD-2025-515515 | B13: 45660 | C13: =MONTH(B13) -> 1 | D13: =B13 -> 45660 | E13: =IF(AND(MONTH(B13)>=1,MONTH(B13)<=3),"Quarter 1",IF(AND(MONTH(B13)>=4,MONTH(B13)<=6),"Quarter 2",IF(AND(MONTH(B13)>=7,MONTH(B13)<=9),"Quarter 3",IF(AND(MONTH(B13)>=10,MONTH(B13)<=12),"Quarter 4")))) -> Quarter 1 | F13: 45680 | G13: =IF(B13>F13,B13+7,F13) -> 45680 | H13: =G13-B13 -> 20 | I13: =IF(H13<=7,"Ontime","Delayed ") -> Delayed | J13: Asia | K13: Japan | L13: Osaka | M13: Corporate | N13: Distributor | O13: F. Müller | P13: Phones | Q13: PHN-7019 | R13: 908.6 | S13: 691.37 | T13: =IF(S13<=0,R13,S13) -> 691.37 | U13: =(1+'10. Whatif Control pannel'!$B$6)*T13 -> 774.3344 | V13: =IF(T13<=_xlfn.PERCENTILE.INC(T13:T644,33%),"Low",IF(T13<=_xlfn.PERCENTILE.INC(T13:T644,67%),"Medium","High")) -> Low | W13: 0.25 | X13: =IF(W13>0.2,"High Discount","Okay") -> High Discount | Y13: =IF(W13<=0.25,W13,'10. Whatif Control pannel'!$B$2) -> 0.25 | Z13: 20 | AA13: =(1+'10. Whatif Control pannel'!$B$10)*Z13 -> 24 | AB13: =T13*Z13*(1-W13) -> 10370.55 | AC13: =U13*AA13*(1-Y13) -> 13938.019 | AD13: =R13*Z13 -> 18172 | AE13: =AB13-AD13 -> -7801.45 | AF13: =AC13-AD13 -> -4233.9808 | AG13: =IF(AB13=0,0,AE13/AB13) -> -0.75226965
... A633: ORD-2025-728935 | B633: 45716 | C633: =MONTH(B633) -> 2 | D633: =B633 -> 45716 | E633: =IF(AND(MONTH(B633)>=1,MONTH(B633)<=3),"Quarter 1",IF(AND(MONTH(B633)>=4,MONTH(B633)<=6),"Quarter 2",IF(AND(MONTH(B633)>=7,MONTH(B633)<=9),"Quarter 3",IF(AND(MONTH(B633)>=10,MONTH(B633)<=12),"Quarter 4")))) -> Quarter 1 | F633: 45726 | G633: =IF(B633>F633,B633+7,F633) -> 45726 | H633: =G633-B633 -> 10 | I633: =IF(H633<=7,"Ontime","Delayed ") -> Delayed | J633: Asia | K633: Japan | L633: Osaka | M633: Education | N633: Distributor | O633: N. Brown | P633: Laptops | Q633: LAP-3017 | R633: 51.86 | S633: 45.98 | T633: =IF(S633<=0,R633,S633) -> 45.98 | U633: =(1+'10. Whatif Control pannel'!$B$6)*T633 -> 51.4976 | V633: =IF(T633<=_xlfn.PERCENTILE.INC(T633:T1264,33%),"Low",IF(T633<=_xlfn.PERCENTILE.INC(T633:T1264,67%),"Medium","High")) -> Low | W633: 0.173 | X633: =IF(W633>0.2,"High Discount","Okay") -> Okay | Y633: =IF(W633<=0.25,W633,'10. Whatif Control pannel'!$B$2) -> 0.173 | Z633: 7 | AA633: =(1+'10. Whatif Control pannel'!$B$10)*Z633 -> 8.4 | AB633: =T633*Z633*(1-W633) -> 266.17822 | AC633: =U633*AA633*(1-Y633) -> 357.74353 | AD633: =R633*Z633 -> 363.02 | AE633: =AB633-AD633 -> -96.84178 | AF633: =AC633-AD633 -> -5.2764723 | AG633: =IF(AB633=0,0,AE633/AB633) -> -0.36382308
AB637: =SUM(AB2:AB633) -> 11024296 | AC637: =SUM(AC2:AC633) -> 14886303 | AE637: =SUM(AE2:AE633) -> 3496548.5 | AF637: =SUM(AF2:AF633) -> 7358555.4
AD638: =AB637/632 -> 17443.507

Sheet 2. Region Hierachy Pivot Table
A3: Region | B3: Country | C3: City
A4: Africa
B5: Kenya
B6: Nigeria
C7: Abuja
C8: Lagos
C9: Port Harcourt
C10: Unknown city
B11: South Africa
C12: Cape Town
C13: Durban
C14: Johannesburg
A15: Americas
B16: Brazil
C17: Brasília
C18: Rio de Janeiro
C19: São Paulo
C20: Unknown city
B21: Canada
C22: Montreal
C23: Toronto
C24: Unknown city
C25: Vancouver
B26: USA
C27: Austin
C28: Chicago
C29: New York
C30: San Francisco
A31: Asia
B32: China
C33: Beijing
C34: Shanghai
C35: Shenzhen
C36: Unknown city
B37: India
C38: Bengaluru
C39: Delhi
C40: Hyderabad
C41: Mumbai
C42: Unknown city
...

Sheet 3.ProductCategory &PriceBands
A3: Count of Derived Price Band | B3: Derived Price Band
A4: ProductCategory | B4: High | C4: Low | D4: Medium | E4: Grand Total
A5: Accessories | B5: 25 | C5: 32 | D5: 31 | E5: 88
A6: Components | B6: 34 | C6: 31 | D6: 26 | E6: 91
A7: Laptops | B7: 37 | C7: 22 | D7: 23 | E7: 82
A8: Monitors | B8: 25 | C8: 35 | D8: 34 | E8: 94
A9: Networking | B9: 36 | C9: 27 | D9: 23 | E9: 86
A10: Phones | B10: 27 | C10: 30 | D10: 31 | E10: 88
A11: Printers | B11: 25 | C11: 42 | D11: 36 | E11: 103
A12: Grand Total | B12: 209 | C12: 219 | D12: 204 | E12: 632

Sheet 4. Cohort analysis
A3: Country | B3: Years | C3: OrderDate | D3: Sum of GrossRevenue
A4: Brazil | D4: 1037432.5
B5: 2023
C6: Jan | D6: 1801.4076
C7: Feb | D7: 24894.431
C8: Mar | D8: 24523.007
C9: Apr | D9: 12248.676
C10: May | D10: 27194.152
C11: Jun | D11: 46991.747
C12: Jul | D12: 93430.735
C13: Aug | D13: 37330.003
C14: Sep | D14: 7071.6331
C15: Oct | D15: 16213.633
C16: Nov | D16: 24161.263
C17: Dec | D17: 61471.697
B18: 2024
C19: Jan | D19: 8567.3925
C20: Feb | D20: 39239.198
C21: Mar | D21: 110.1492
C22: Apr | D22: 57491.063
C23: May | D23: 9469.7678
C24: Jun | D24: 41658.527
C25: Jul | D25: 10937.52
C26: Aug | D26: 41358.42
C27: Sep | D27: 85419.018
C28: Nov | D28: 11939.431
B29: 2025
C30: Jan | D30: 22987.328
C31: Feb | D31: 70563.592
C32: Mar | D32: 16257.34
C33: Apr | D33: 68920.107
C34: May | D34: 67158.245
C35: Jul | D35: 38096.184
C36: Aug | D36: 45754.744
C37: Sep | D37: 24172.045
A38: Canada | D38: 882622.98
B39: 2023
C40: Jan | D40: 4141.76
C41: Feb | D41: 26150.364
C42: Mar | D42: 17453.344
...

Sheet 5. ABC Analysis
A3: ProductCategory | B3: SKU | C3: Sum of GrossRevenue | D3: Percentage | E3: Cumulative% | F3: ABC Analysis
A4: Accessories | C4: 1394856.8 | D4: =SUM(D5:D92) -> 1
B5: ACC-6626 | C5: 79082.507 | D5: =C5/$C$4 -> 0.056695788 | E5: =D5 -> 0.056695788 | F5: =IF(E5<=80%,"A",IF(E5<=95%,"B",IF(E5<=100%,"C"," "))) -> A
B6: ACC-1770 | C6: 63480.9 | D6: =C6/$C$4 -> 0.045510692 | E6: =E5+D6 -> 0.10220648 | F6: =IF(E6<=80%,"A",IF(E6<=95%,"B",IF(E6<=100%,"C"," "))) -> A
B7: ACC-2988 | C7: 53034.364 | D7: =C7/$C$4 -> 0.038021367 | E7: =E6+D7 -> 0.14022785 | F7: =IF(E7<=80%,"A",IF(E7<=95%,"B",IF(E7<=100%,"C"," "))) -> A
B8: ACC-9283 | C8: 46450.26 | D8: =C8/$C$4 -> 0.033301095 | E8: =E7+D8 -> 0.17352894 | F8: =IF(E8<=80%,"A",IF(E8<=95%,"B",IF(E8<=100%,"C"," "))) -> A
B9: ACC-9533 | C9: 43084.872 | D9: =C9/$C$4 -> 0.030888383 | E9: =E8+D9 -> 0.20441733 | F9: =IF(E9<=80%,"A",IF(E9<=95%,"B",IF(E9<=100%,"C"," "))) -> A
B10: ACC-8098 | C10: 38096.184 | D10: =C10/$C$4 -> 0.027311896 | E10: =E9+D10 -> 0.23172922 | F10: =IF(E10<=80%,"A",IF(E10<=95%,"B",IF(E10<=100%,"C"," "))) -> A
B11: ACC-4490 | C11: 35396.278 | D11: =C11/$C$4 -> 0.02537628 | E11: =E10+D11 -> 0.2571055 | F11: =IF(E11<=80%,"A",IF(E11<=95%,"B",IF(E11<=100%,"C"," "))) -> A
B12: ACC-7838 | C12: 35167.745 | D12: =C12/$C$4 -> 0.02521244 | E12: =E11+D12 -> 0.28231794 | F12: =IF(E12<=80%,"A",IF(E12<=95%,"B",IF(E12<=100%,"C"," "))) -> A
B13: ACC-5177 | C13: 34139.16 | D13: =C13/$C$4 -> 0.024475028 | E13: =E12+D13 -> 0.30679297 | F13: =IF(E13<=80%,"A",IF(E13<=95%,"B",IF(E13<=100%,"C"," "))) -> A
B14: ACC-9162 | C14: 33062.236 | D14: =C14/$C$4 -> 0.023702961 | E14: =E13+D14 -> 0.33049593 | F14: =IF(E14<=80%,"A",IF(E14<=95%,"B",IF(E14<=100%,"C"," "))) -> A
B15: ACC-7078 | C15: 32086.376 | D15: =C15/$C$4 -> 0.023003347 | E15: =E14+D15 -> 0.35349928 | F15: =IF(E15<=80%,"A",IF(E15<=95%,"B",IF(E15<=100%,"C"," "))) -> A
B16: ACC-1375 | C16: 31513.085 | D16: =C16/$C$4 -> 0.022592344 | E16: =E15+D16 -> 0.37609162 | F16: =IF(E16<=80%,"A",IF(E16<=95%,"B",IF(E16<=100%,"C"," "))) -> A
B17: ACC-1659 | C17: 28386.016 | D17: =C17/$C$4 -> 0.020350487 | E17: =E16+D17 -> 0.39644211 | F17: =IF(E17<=80%,"A",IF(E17<=95%,"B",IF(E17<=100%,"C"," "))) -> A
... B92: ACC-6777 | C92: 18.65984 | D92: =C92/$C$4 -> 1.3377602e-05 | E92: =E91+D92 -> 1 | F92: =IF(E92<=80%,"A",IF(E92<=95%,"B",IF(E92<=100%,"C"," "))) -> C
A93: Components | C93: 1545647
B94: CMP-8851 | C94: 139277.83 | D94: =C94/$C$93 -> 0.090109728 | E94: =D94 -> 0.090109728 | F94: =IF(E94<=80%,"A",IF(E94<=95%,"B",IF(E94<=100%,"C"," "))) -> A
B95: CMP-3938 | C95: 84136.12 | D95: =C95/$C$93 -> 0.05443424 | E95: =E94+D95 -> 0.14454397 | F95: =IF(E95<=80%,"A",IF(E95<=95%,"B",IF(E95<=100%,"C"," "))) -> A
B96: CMP-2040 | C96: 65111.386 | D96: =C96/$C$93 -> 0.042125651 | E96: =E95+D96 -> 0.18666962 | F96: =IF(E96<=80%,"A",IF(E96<=95%,"B",IF(E96<=100%,"C"," "))) -> A
B97: CMP-3731 | C97: 60928.502 | D97: =C97/$C$93 -> 0.039419416 | E97: =E96+D97 -> 0.22608904 | F97: =IF(E97<=80%,"A",IF(E97<=95%,"B",IF(E97<=100%,"C"," "))) -> A
B98: CMP-8127 | C98: 50296.415 | D98: =C98/$C$93 -> 0.032540687 | E98: =E97+D98 -> 0.25862972 | F98: =IF(E98<=80%,"A",IF(E98<=95%,"B",IF(E98<=100%,"C"," "))) -> A
B99: CMP-2096 | C99: 48097.911 | D99: =C99/$C$93 -> 0.031118303 | E99: =E98+D99 -> 0.28974802 | F99: =IF(E99<=80%,"A",IF(E99<=95%,"B",IF(E99<=100%,"C"," "))) -> A
B100: CMP-5006 | C100: 41419.524 | D100: =C100/$C$93 -> 0.026797532 | E100: =E99+D100 -> 0.31654556 | F100: =IF(E100<=80%,"A",IF(E100<=95%,"B",IF(E100<=100%,"C"," "))) -> A
B101: CMP-1940 | C101: 40476.013 | D101: =C101/$C$93 -> 0.0261871 | E101: =E100+D101 -> 0.34273266 | F101: =IF(E101<=80%,"A",IF(E101<=95%,"B",IF(E101<=100%,"C"," "))) -> A
B102: CMP-8002 | C102: 33687.502 | D102: =C102/$C$93 -> 0.021795081 | E102: =E101+D102 -> 0.36452774 | F102: =IF(E102<=80%,"A",IF(E102<=95%,"B",IF(E102<=100%,"C"," "))) -> A
B103: CMP-1156 | C103: 33308.55 | D103: =C103/$C$93 -> 0.021549908 | E103: =E102+D103 -> 0.38607765 | F103: =IF(E103<=80%,"A",IF(E103<=95%,"B",IF(E103<=100%,"C"," "))) -> A
B104: CMP-6529 | C104: 32335.218 | D104: =C104/$C$93 -> 0.020920183 | E104: =E103+D104 -> 0.40699783 | F104: =IF(E104<=80%,"A",IF(E104<=95%,"B",IF(E104<=100%,"C"," "))) -> A
B105: CMP-6971 | C105: 27701.57 | D105: =C105/$C$93 -> 0.017922314 | E105: =E104+D105 -> 0.42492014 | F105: =IF(E105<=80%,"A",IF(E105<=95%,"B",IF(E105<=100%,"C"," "))) -> A
B106: CMP-6392 | C106: 27676.35 | D106: =C106/$C$93 -> 0.017905997 | E106: =E105+D106 -> 0.44282614 | F106: =IF(E106<=80%,"A",IF(E106<=95%,"B",IF(E106<=100%,"C"," "))) -> A
... B183: CMP-1632 | C183: 97.0154 | D183: =C183/$C$93 -> 6.2766854e-05 | E183: =E182+D183 -> 1 | F183: =IF(E183<=80%,"A",IF(E183<=95%,"B",IF(E183<=100%,"C"," "))) -> C
A184: Laptops | C184: 1711094.4
B185: LAP-8910 | C185: 102122.94 | D185: =C185/$C$184 -> 0.059682823 | E185: =D185 -> 0.059682823 | F185: =IF(E185<=80%,"A",IF(E185<=95%,"B",IF(E185<=100%,"C"," "))) -> A
B186: LAP-3904 | C186: 82514.712 | D186: =C186/$C$184 -> 0.048223355 | E186: =E185+D186 -> 0.10790618 | F186: =IF(E186<=80%,"A",IF(E186<=95%,"B",IF(E186<=100%,"C"," "))) -> A
B187: LAP-8214 | C187: 65119.33 | D187: =C187/$C$184 -> 0.038057123 | E187: =E186+D187 -> 0.1459633 | F187: =IF(E187<=80%,"A",IF(E187<=95%,"B",IF(E187<=100%,"C"," "))) -> A
B188: LAP-5763 | C188: 65066.934 | D188: =C188/$C$184 -> 0.038026502 | E188: =E187+D188 -> 0.1839898 | F188: =IF(E188<=80%,"A",IF(E188<=95%,"B",IF(E188<=100%,"C"," "))) -> A
B189: LAP-6499 | C189: 64192.977 | D189: =C189/$C$184 -> 0.037515743 | E189: =E188+D189 -> 0.22150555 | F189: =IF(E189<=80%,"A",IF(E189<=95%,"B",IF(E189<=100%,"C"," "))) -> A
B190: LAP-1739 | C190: 58526.831 | D190: =C190/$C$184 -> 0.034204327 | E190: =E189+D190 -> 0.25570987 | F190: =IF(E190<=80%,"A",IF(E190<=95%,"B",IF(E190<=100%,"C"," "))) -> A
B191: LAP-8825 | C191: 58057.65 | D191: =C191/$C$184 -> 0.033930127 | E191: =E190+D191 -> 0.28964 | F191: =IF(E191<=80%,"A",IF(E191<=95%,"B",IF(E191<=100%,"C"," "))) -> A
B192: LAP-7523 | C192: 44173.628 | D192: =C192/$C$184 -> 0.025816009 | E192: =E191+D192 -> 0.31545601 | F192: =IF(E192<=80%,"A",IF(E192<=95%,"B",IF(E192<=100%,"C"," "))) -> A
...

Sheet 6. Salesperson productivity
A3: Salesperson | B3: Distinct Count of OrderID | C3: Sum of GrossRevenue | D3: Sum of GrossProfit | E3: Distinct Count of Month | F3: Revenue/Order | G3: Orders/Month | H3: Gross Profit/Order
A4: A. Patel | B4: 46 | C4: 877159.52 | D4: 281944.47 | E4: 12 | F4: =C4/B4 -> 19068.685 | G4: =B4/E4 -> 3.8333333 | H4: =D4/B4 -> 6129.2276
A5: B. Chen | B5: 48 | C5: 893735.66 | D5: 315969.97 | E5: 12 | F5: =C5/B5 -> 18619.493 | G5: =B5/E5 -> 4 | H5: =D5/B5 -> 6582.7077
A6: C. Otieno | B6: 37 | C6: 685111.86 | D6: 225695.02 | E6: 12 | F6: =C6/B6 -> 18516.537 | G6: =B6/E6 -> 3.0833333 | H6: =D6/B6 -> 6099.8654
A7: D. Smith | B7: 38 | C7: 594149.69 | D7: 168406.43 | E7: 11 | F7: =C7/B7 -> 15635.518 | G7: =B7/E7 -> 3.4545455 | H7: =D7/B7 -> 4431.7481
A8: E. Garcia | B8: 34 | C8: 543846.44 | D8: 204981.34 | E8: 12 | F8: =C8/B8 -> 15995.484 | G8: =B8/E8 -> 2.8333333 | H8: =D8/B8 -> 6028.863
A9: F. Müller | B9: 51 | C9: 812637.17 | D9: 251733.01 | E9: 12 | F9: =C9/B9 -> 15934.062 | G9: =B9/E9 -> 4.25 | H9: =D9/B9 -> 4935.9414
A10: G. Dubois | B10: 30 | C10: 510653.71 | D10: 172441.87 | E10: 11 | F10: =C10/B10 -> 17021.79 | G10: =B10/E10 -> 2.7272727 | H10: =D10/B10 -> 5748.0624
A11: H. Kim | B11: 45 | C11: 760776.21 | D11: 200228.72 | E11: 12 | F11: =C11/B11 -> 16906.138 | G11: =B11/E11 -> 3.75 | H11: =D11/B11 -> 4449.5272
A12: I. Johnson | B12: 38 | C12: 556078.75 | D12: 154934.77 | E12: 11 | F12: =C12/B12 -> 14633.651 | G12: =B12/E12 -> 3.4545455 | H12: =D12/B12 -> 4077.2309
A13: J. Njeri | B13: 50 | C13: 802384.66 | D13: 273113.11 | E13: 11 | F13: =C13/B13 -> 16047.693 | G13: =B13/E13 -> 4.5454545 | H13: =D13/B13 -> 5462.2622
A14: K. Singh | B14: 44 | C14: 883348.13 | D14: 278762.27 | E14: 12 | F14: =C14/B14 -> 20076.094 | G14: =B14/E14 -> 3.6666667 | H14: =D14/B14 -> 6335.5061
A15: L. Okafor | B15: 46 | C15: 853038.52 | D15: 269716.55 | E15: 12 | F15: =C15/B15 -> 18544.316 | G15: =B15/E15 -> 3.8333333 | H15: =D15/B15 -> 5863.4033
... A20: Grand Total | B20: 631 | C20: 11024296 | D20: 3496548.5 | E20: 12 | F20: =C20/B20 -> 17471.151 | G20: =B20/E20 -> 52.583333 | H20: =D20/B20 -> 5541.2813

Sheet 7.Channel mix & cannibalization
A3: Region | B3: Channel | C3: Sum of GrossRevenue
A4: Africa | C4: 2612548.9
B5: Direct | C5: 461428.96
B6: Distributor | C6: 623894.11
B7: Marketplace | C7: 527467.87
B8: Not provided | C8: 32716.924
B9: Online | C9: 433406.34
B10: Retail | C10: 533634.72
A11: Americas | C11: 2688750
B12: Direct | C12: 751887.69
B13: Distributor | C13: 568425.23
B14: Marketplace | C14: 366375.93
B15: Not provided | C15: 9256.14
B16: Online | C16: 689951.45
B17: Retail | C17: 302853.58
A18: Asia | C18: 2841471.9
B19: Direct | C19: 642428.79
B20: Distributor | C20: 509418.81
B21: Marketplace | C21: 541441.74
B22: Not provided | C22: 41379.395
B23: Online | C23: 413661.51
B24: Retail | C24: 693141.68
A25: Europe | C25: 2881525.3
B26: Direct | C26: 842614.45
B27: Distributor | C27: 318736.67
B28: Marketplace | C28: 632884.44
B29: Not provided | C29: 18050.446
B30: Online | C30: 585406.72
B31: Retail | C31: 483832.61
A32: Grand Total | C32: 11024296

Sheet 8. Service level proxy
A1: On-Time | B1: Ontime
A3: Count of On-Time | B3: ProductCategory
A4: Country | B4: Accessories | C4: Components | D4: Laptops | E4: Monitors | F4: Networking | G4: Phones | H4: Printers | I4: Grand Total
A5: Brazil | B5: 0.023255814 | C5: 0.0058139535 | D5: 0.0058139535 | E5: 0.01744186 | F5: 0.011627907 | G5: 0.029069767 | H5: 0.011627907 | I5: 0.10465116
A6: Canada | B6: 0.011627907 | C6: 0.01744186 | D6: 0.011627907 | E6: 0 | F6: 0 | G6: 0 | H6: 0.011627907 | I6: 0.052325581
A7: China | B7: 0.01744186 | C7: 0 | D7: 0.0058139535 | E7: 0.0058139535 | F7: 0.023255814 | G7: 0.0058139535 | H7: 0 | I7: 0.058139535
A8: France | B8: 0.0058139535 | C8: 0.01744186 | D8: 0.011627907 | E8: 0.01744186 | F8: 0.011627907 | G8: 0 | H8: 0.011627907 | I8: 0.075581395
A9: Germany | B9: 0.023255814 | C9: 0.011627907 | D9: 0.011627907 | E9: 0.0058139535 | F9: 0.0058139535 | G9: 0.0058139535 | H9: 0.0058139535 | I9: 0.069767442
A10: India | B10: 0.011627907 | C10: 0.011627907 | D10: 0.0058139535 | E10: 0.011627907 | F10: 0.0058139535 | G10: 0.011627907 | H10: 0.011627907 | I10: 0.069767442
A11: Japan | B11: 0.0058139535 | C11: 0.01744186 | D11: 0.01744186 | E11: 0.011627907 | F11: 0.0058139535 | G11: 0.0058139535 | H11: 0.01744186 | I11: 0.081395349
A12: Kenya | B12: 0.023255814 | C12: 0.0058139535 | D12: 0.040697674 | E12: 0 | F12: 0.011627907 | G12: 0.011627907 | H12: 0.0058139535 | I12: 0.098837209
A13: Nigeria | B13: 0.034883721 | C13: 0.011627907 | D13: 0.01744186 | E13: 0.01744186 | F13: 0.0058139535 | G13: 0.0058139535 | H13: 0.01744186 | I13: 0.11046512
A14: South Africa | B14: 0.011627907 | C14: 0.029069767 | D14: 0.011627907 | E14: 0.0058139535 | F14: 0.011627907 | G14: 0.011627907 | H14: 0.0058139535 | I14: 0.087209302
A15: United Kingdom | B15: 0.0058139535 | C15: 0.011627907 | D15: 0.023255814 | E15: 0.011627907 | F15: 0.011627907 | G15: 0.0058139535 | H15: 0.01744186 | I15: 0.087209302
A16: USA | B16: 0.011627907 | C16: 0.011627907 | D16: 0.0058139535 | E16: 0.0058139535 | F16: 0.029069767 | G16: 0.0058139535 | H16: 0.034883721 | I16: 0.10465116
A17: Grand Total | B17: 0.18604651 | C17: 0.15116279 | D17: 0.16860465 | E17: 0.11046512 | F17: 0.13372093 | G17: 0.098837209 | H17: 0.15116279 | I17: 1

Sheet 9. Price Compliance
A1: DiscountPct> 20% | B1: High Discount
A3: Count of OrderID | B3: Salesperson
A4: Region | B4: A. Patel | C4: B. Chen | D4: C. Otieno | E4: D. Smith | F4: E. Garcia | G4: F. Müller | H4: G. Dubois | I4: H. Kim | J4: I. Johnson | K4: J. Njeri | L4: K. Singh | M4: L. Okafor | N4: M. Rossi | O4: N. Brown | P4: O. Wang | Q4: Unknown | R4: Grand Total
A5: Africa | B5: 3 | C5: 0 | D5: 2 | E5: 2 | F5: 1 | G5: 0 | H5: 0 | I5: 1 | J5: 2 | K5: 3 | L5: 0 | M5: 2 | N5: 5 | O5: 0 | P5: 0 | Q5: 1 | R5: 22
A6: Americas | B6: 5 | C6: 1 | D6: 2 | E6: 4 | F6: 0 | G6: 1 | H6: 1 | I6: 0 | J6: 5 | K6: 0 | L6: 1 | M6: 3 | N6: 2 | O6: 1 | P6: 0 | Q6: 1 | R6: 27
A7: Asia | B7: 0 | C7: 2 | D7: 3 | E7: 1 | F7: 0 | G7: 3 | H7: 1 | I7: 2 | J7: 1 | K7: 2 | L7: 1 | M7: 3 | N7: 0 | O7: 1 | P7: 4 | Q7: 0 | R7: 24
A8: Europe | B8: 1 | C8: 2 | D8: 1 | E8: 1 | F8: 2 | G8: 0 | H8: 1 | I8: 1 | J8: 1 | K8: 1 | L8: 2 | M8: 0 | N8: 1 | O8: 3 | P8: 0 | Q8: 0 | R8: 17
A9: Grand Total | B9: 9 | C9: 5 | D9: 8 | E9: 8 | F9: 3 | G9: 4 | H9: 3 | I9: 4 | J9: 9 | K9: 6 | L9: 4 | M9: 8 | N9: 8 | O9: 5 | P9: 4 | Q9: 2 | R9: 90

Sheet 10. Whatif Control pannel
B1: DiscountPct
A2: Global Discout Cap(0%-25%) | B2: =F2/100 -> 0.23 | F2: 23
A6: UnitCost Inflation factor(0%-15%) | B6: =F6/100 -> 0.12 | F6: 12
A10: Quantity Uplift(0%-20%) | B10: =F10/100 -> 0.2 | F10: 20
A13: METRICS COMPARISON
A14: Gross Revenue | B14: ='1. Staging Table'!AB637 -> 11024296
A15: WhatIf GrossRevenue | B15: ='1. Staging Table'!AC637 -> 14886303
A17: GrossProfit | B17: ='1. Staging Table'!AE637 -> 3496548.5
A18: WhatIf GrossProfit | B18: ='1. Staging Table'!AF637 -> 7358555.4

Sheet 11. Revenue by Month pivottable
A3: Month | B3: Sum of GrossRevenue
A4: Jan | B4: 701241.31
A5: Feb | B5: 978103.94
A6: Mar | B6: 798978.3
A7: Apr | B7: 947246.58
A8: May | B8: 1262173.9
A9: Jun | B9: 1316182.1
A10: Jul | B10: 1313062.3
A11: Aug | B11: 1089608.8
A12: Sep | B12: 661159.43
A13: Oct | B13: 658776.06 | L13: =GETPIVOTDATA("GrossRevenue",$A$3,"Month",4)/GETPIVOTDATA("GrossRevenue",$A$3) -> #REF!
A14: Nov | B14: 543953.69
A15: Dec | B15: 753809.8
A16: Grand Total | B16: 11024296

Sheet 12.Profit by Region and Channel
A3: Region | B3: Channel | C3: Gross Profit
A4: Africa | C4: 852576.93
B5: Direct | C5: 177919.82
B6: Distributor | C6: 192042.35
B7: Marketplace | C7: 164839.3
B8: Not provided | C8: 16237.344
B9: Online | C9: 145453.95
B10: Retail | C10: 156084.17
A11: Americas | C11: 862340.77
B12: Direct | C12: 258674.93
B13: Distributor | C13: 175298.68
B14: Marketplace | C14: 96609.648
B15: Not provided | C15: 777.96
B16: Online | C16: 261943.84
B17: Retail | C17: 69035.709
A18: Asia | C18: 831257.73
B19: Direct | C19: 229217.48
B20: Distributor | C20: 151146.75
B21: Marketplace | C21: 128045.01
B22: Not provided | C22: 20547.545
B23: Online | C23: 149042.39
B24: Retail | C24: 153258.56
A25: Europe | C25: 950373.07
B26: Direct | C26: 292716.95
B27: Distributor | C27: 105550.85
B28: Marketplace | C28: 174900.72
B29: Not provided | C29: 8028.7065
B30: Online | C30: 200067.16
B31: Retail | C31: 169108.67
A32: Grand Total | C32: 3496548.5

Sheet 13.Top 10 SKUs by Revenue
A3: SKU | B3: Sum of GrossRevenue
A4: NET-5523 | B4: 79548.756
A5: NET-5987 | B5: 82141.34
A6: LAP-3904 | B6: 82514.712
A7: CMP-3938 | B7: 84136.12
A8: MON-6699 | B8: 85637.74
A9: MON-2266 | B9: 87404.93
A10: MON-6962 | B10: 92715.25
A11: LAP-8910 | B11: 102122.94
A12: NET-2365 | B12: 109244
A13: CMP-8851 | B13: 139277.83
A14: Grand Total | B14: 944743.62

Sheet 14. Discount Outliers
A3: OrderID | B3: DiscountPct > 0.25
A4: ORD-2023-261081 | B4: 0.565
A5: ORD-2023-290279 | B5: 0.257
A6: ORD-2023-368449 | B6: 0.357
A7: ORD-2023-382272 | B7: 0.343
A8: ORD-2023-422918 | B8: 0.292
A9: ORD-2023-521818 | B9: 0.344
A10: ORD-2023-613287 | B10: 0.265
A11: ORD-2023-766015 | B11: 0.282
A12: ORD-2023-825084 | B12: 0.299
A13: ORD-2023-944052 | B13: 0.27
A14: ORD-2024-155337 | B14: 0.278
A15: ORD-2024-232632 | B15: 0.259
... A35: Grand Total | B35: 9.091

Sheet 15. DASHBOARD
